Workbook

Sheet insurance_policy_data
A1: Policy_ID | B1: Applicant_Age | C1: Gender | D1: Marital_Status | E1: Vehicle_Year | F1: Vehicle_Make | G1: Vehicle_Model | H1: Annual_Mileage | I1: Years_Driving_Exp | J1: At_Fault_Accidents_5yr | K1: Speeding_Tickets_3yr | L1: DUI | M1: Credit_Score | N1: Coverage_Type | O1: Prior_Insurance_Carrier | P1: Claim_Amount_Last_Year | Q1: State | R1: Claim Last Year
A2: AUTO-1002 | B2: 23 | C2: M | D2: Married | E2: 2016 | F2: Jeep | G2: Wrangler | H2: 21390 | I2: 6 | J2: 2 | K2: 3 | L2: Y | M2: 729 | N2: COMP | O2: Nationwide | P2: 1200 | Q2: TX | R2: =IF(P2>0, "Y", "N") -> Y
A3: AUTO-1003 | B3: 66 | C3: M | D3: Widowed | E3: 2010 | F3: Ford | G3: F-150 | H3: 10055 | I3: 48 | J3: 0 | K3: 0 | L3: N | M3: 399 | N3: COLL | O3: USAA | P3: 1200 | Q3: CA | R3: =IF(P3>0, "Y", "N") -> Y
A4: AUTO-1004 | B4: 64 | C4: F | D4: Single | E4: 2012 | F4: Toyota | G4: Corolla | H4: 23599 | I4: 44 | J4: 0 | K4: 2 | L4: Y | M4: 371 | N4: COMP | O4: Allstate | P4: 1200 | Q4: NY | R4: =IF(P4>0, "Y", "N") -> Y
A5: AUTO-1007 | B5: 35 | C5: M | D5: Married | E5: 2018 | F5: Ford | G5: F-150 | H5: 24477 | I5: 16 | J5: 1 | K5: 3 | L5: N | M5: 446 | N5: COLL | O5: Progressive | P5: 500 | Q5: IN | R5: =IF(P5>0, "Y", "N") -> Y
A6: AUTO-1008 | B6: 52 | C6: M | D6: Widowed | E6: 2018 | F6: Chevrolet | G6: Malibu | H6: 10186 | I6: 35 | J6: 1 | K6: 1 | L6: Y | M6: 348 | N6: COMP | O6: Progressive | P6: 0 | Q6: VA | R6: =IF(P6>0, "Y", "N") -> N
A7: AUTO-1009 | B7: 56 | C7: M | D7: Widowed | E7: 2012 | F7: Jeep | G7: Grand Cherokee | H7: 20338 | I7: 38 | J7: 1 | K7: 0 | L7: Y | M7: 849 | N7: COLL | O7: USAA | P7: 0 | Q7: MI | R7: =IF(P7>0, "Y", "N") -> N
A8: AUTO-1010 | B8: 45 | C8: M | D8: Widowed | E8: 2000 | F8: Ford | G8: Escape | H8: 8854 | I8: 25 | J8: 0 | K8: 3 | L8: N | M8: 819 | N8: LIAB | O8: Allstate | P8: 0 | Q8: AZ | R8: =IF(P8>0, "Y", "N") -> N
A9: AUTO-1011 | B9: 66 | C9: M | D9: Single | E9: 2019 | F9: Ford | G9: Focus | H9: 3638 | I9: 50 | J9: 0 | K9: 1 | L9: Y | M9: 359 | N9: COMP | O9: AmericaNFamily | P9: 0 | Q9: NY | R9: =IF(P9>0, "Y", "N") -> N
A10: AUTO-1013 | B10: 66 | C10: F | D10: Married | E10: 2022 | F10: Ford | G10: Focus | H10: 24295 | I10: 48 | J10: 1 | K10: 2 | L10: N | M10: 423 | N10: COMP | O10: Allstate | P10: 0 | Q10: WA | R10: =IF(P10>0, "Y", "N") -> N
A11: AUTO-1014 | B11: 19 | C11: F | D11: Married | E11: 2018 | F11: Honda | G11: Civic | H11: 5326 | I11: 3 | J11: 0 | K11: 0 | L11: Y | M11: 638 | N11: COMP | O11: Travelers | P11: 500 | Q11: NC | R11: =IF(P11>0, "Y", "N") -> Y
A12: AUTO-1015 | B12: 60 | C12: F | D12: Married | E12: 2017 | F12: Honda | G12: CR-V | H12: 21711 | I12: 40 | J12: 1 | K12: 0 | L12: N | M12: 716 | N12: COMP | O12: Geico | P12: 0 | Q12: VA | R12: =IF(P12>0, "Y", "N") -> N
A13: AUTO-1016 | B13: 40 | C13: F | D13: Widowed | E13: 2014 | F13: Toyota | G13: RAV4 | H13: 24412 | I13: 24 | J13: 0 | K13: 1 | L13: N | M13: 411 | N13: COMP | O13: Allstate | P13: 500 | Q13: IN | R13: =IF(P13>0, "Y", "N") -> Y
... A319: AUTO-1349 | B319: 57 | C319: M | D319: Widowed | E319: 2020 | F319: Honda | G319: Civic | H319: 23990 | I319: 39 | J319: 1 | K319: 3 | L319: Y | M319: 714 | N319: COMP | O319: Geico | P319: 0 | Q319: WA | R319: =IF(P319>0, "Y", "N") -> N

Sheet Data Distribution
A1: Distribution
A4: Row Labels | B4: Count of Policy_ID | D4: Row Labels | E4: Count of Policy_ID | G4: Experience | H4: Count of Policy_ID | J4: DUI | K4: Count of Policy_ID | M4: Row Labels | N4: Count of Policy_ID
A5: 18-27 | B5: 57 | D5: 2000-2004 | E5: 59 | G5: 0-9 | H5: 50 | J5: N | K5: 122 | M5: Allstate | N5: 39 | P5: Claim Cost Last Year | Q5: Count of Policy_ID
A6: 28-37 | B6: 44 | D6: 2005-2009 | E6: 49 | G6: 10-19 | H6: 52 | J6: Y | K6: 196 | M6: AmericaNFamily | N6: 30 | P6: 0 | Q6: 131
A7: 38-47 | B7: 54 | D7: 2010-2014 | E7: 67 | G7: 20-29 | H7: 51 | J7: Grand Total | K7: 318 | M7: Farmers | N7: 38 | P7: 500 | Q7: 46
A8: 48-57 | B8: 51 | D8: 2015-2019 | E8: 72 | G8: 30-39 | H8: 54 | M8: Geico | N8: 30 | P8: 1200 | Q8: 37
A9: 58-67 | B9: 60 | D9: 2020-2024 | E9: 71 | G9: 40-49 | H9: 60 | J9: Credit Score | K9: Count of Policy_ID | M9: LibertYMutual | N9: 25 | P9: 3000 | Q9: 33
A10: 68-77 | B10: 52 | D10: Grand Total | E10: 318 | G10: 50-59 | H10: 51 | J10: 300-409 | K10: 67 | M10: Nationwide | N10: 35 | P10: 7500 | Q10: 39
A11: Grand Total | B11: 318 | G11: Grand Total | H11: 318 | J11: 410-519 | K11: 67 | M11: Progressive | N11: 25 | P11: 15000 | Q11: 32
D12: Row Labels | E12: Count of Policy_ID | J12: 520-629 | K12: 68 | M12: State Farm | N12: 23 | P12: Grand Total | Q12: 318
A13: Row Labels | B13: Count of Policy_ID | D13: BMW | E13: 26 | G13: At Fault # | H13: Count of Policy_ID | J13: 630-739 | K13: 71 | M13: Travelers | N13: 43
A14: Divorced | B14: 75 | D14: Chevrolet | E14: 29 | G14: 0 | H14: 142 | J14: 740-850 | K14: 45 | M14: USAA | N14: 30 | P14: Claim Last Year | Q14: Count of Policy_ID
A15: Married | B15: 73 | D15: Ford | E15: 74 | G15: 1 | H15: 130 | J15: Grand Total | K15: 318 | M15: Grand Total | N15: 318 | P15: N | Q15: 131
A16: Single | B16: 82 | D16: Honda | E16: 74 | G16: 2 | H16: 46 | P16: Y | Q16: 187
A17: Widowed | B17: 88 | D17: Jeep | E17: 28 | G17: Grand Total | H17: 318 | J17: Coverage | K17: Count of Policy_ID | M17: Row Labels | N17: Count of Policy_ID | P17: Grand Total | Q17: 318
A18: Grand Total | B18: 318 | D18: Nissan | E18: 34 | J18: COLL | K18: 113 | M18: AZ | N18: 12
D19: Toyota | E19: 53 | G19: Speeding Ticket # | H19: Count of Policy_ID | J19: COMP | K19: 109 | M19: CA | N19: 9
A20: Row Labels | B20: Count of Policy_ID | D20: Grand Total | E20: 318 | G20: 0 | H20: 98 | J20: LIAB | K20: 96 | M20: CA | N20: 1
A21: F | B21: 175 | G21: 1 | H21: 104 | J21: Grand Total | K21: 318 | M21: CO | N21: 20
A22: M | B22: 143 | D22: Annual Mileage | E22: Count of Policy_ID | G22: 2 | H22: 52 | M22: FL | N22: 18
A23: Grand Total | B23: 318 | D23: 3240-6739 | E23: 45 | G23: 3 | H23: 64 | M23: GA | N23: 13
D24: 6740-10239 | E24: 51 | G24: Grand Total | H24: 318 | M24: IL | N24: 15
D25: 10240-13739 | E25: 46 | M25: IN | N25: 14
D26: 13740-17239 | E26: 54 | M26: MA | N26: 14
D27: 17240-20739 | E27: 57 | M27: MD | N27: 21
D28: 20740-24239 | E28: 52 | M28: MI | N28: 22
D29: 24240-27739 | E29: 13 | M29: MO | N29: 22
D30: Grand Total | E30: 318 | M30: NC | N30: 13
M31: NJ | N31: 16
M32: NY | N32: 20
M33: OH | N33: 10
M34: PA | N34: 19
M35: TN | N35: 9
M36: TX | N36: 15
M37: VA | N37: 19
M38: WA | N38: 16
M39: Grand Total | N39: 318

Sheet Sheet1
B2: Applicant Age | C2: Years_Exp | D2: At_Fault_Accidents | E2: credit_score | F2: annual_milage | G2: DUI | H2: Coverage | I2: Cost
B3: =_xlfn.XLOOKUP(insurance_policy_data!B253,Sheet2!$B$3:$B$8,Sheet2!$C$3:$C$8,,-1) -> 1.21 | C3: =_xlfn.XLOOKUP(insurance_policy_data!I253,Sheet2!$E$3:$E$7,Sheet2!$F$3:$F$7,,-1) -> 1.25 | D3: =_xlfn.XLOOKUP(insurance_policy_data!P253,Sheet2!$H$3:$H$5,Sheet2!$I$3:$I$5,,-1) -> 1 | E3: =_xlfn.XLOOKUP(insurance_policy_data!M253,Sheet2!$K$3:$K$7,Sheet2!$L$3:$L$7,,-1) -> 1.39 | F3: =_xlfn.XLOOKUP(insurance_policy_data!H253,Sheet2!$N$3:$N$9,Sheet2!$O$3:$O$9,,-1) -> 1.1 | G3: =_xlfn.XLOOKUP(insurance_policy_data!L253,Sheet2!$Q$3:$Q$4,Sheet2!$R$3:$R$4) -> 0.75 | H3: =_xlfn.XLOOKUP(insurance_policy_data!N253,Sheet2!$T$3:$T$5,Sheet2!$U$3:$U$5,,-1) -> 1 | I3: =(B3*C3*D3*E3*F3*G3*H3)*80 -> 138.75675
B4: =_xlfn.XLOOKUP(insurance_policy_data!B45,Sheet2!$B$3:$B$8,Sheet2!$C$3:$C$8,,-1) -> 1.27 | C4: =_xlfn.XLOOKUP(insurance_policy_data!I45,Sheet2!$E$3:$E$7,Sheet2!$F$3:$F$7,,-1) -> 1.25 | D4: =_xlfn.XLOOKUP(insurance_policy_data!P45,Sheet2!$H$3:$H$5,Sheet2!$I$3:$I$5,,-1) -> 1 | E4: =_xlfn.XLOOKUP(insurance_policy_data!M45,Sheet2!$K$3:$K$7,Sheet2!$L$3:$L$7,,-1) -> 1.26 | F4: =_xlfn.XLOOKUP(insurance_policy_data!H45,Sheet2!$N$3:$N$9,Sheet2!$O$3:$O$9,,-1) -> 1.1 | G4: =_xlfn.XLOOKUP(insurance_policy_data!L45,Sheet2!$Q$3:$Q$4,Sheet2!$R$3:$R$4) -> 0.75 | H4: =_xlfn.XLOOKUP(insurance_policy_data!N45,Sheet2!$T$3:$T$5,Sheet2!$U$3:$U$5,,-1) -> 1.1 | I4: =(B4*C4*D4*E4*F4*G4*H4)*80 -> 145.21815
B5: =_xlfn.XLOOKUP(insurance_policy_data!B317,Sheet2!$B$3:$B$8,Sheet2!$C$3:$C$8,,-1) -> 1.21 | C5: =_xlfn.XLOOKUP(insurance_policy_data!I317,Sheet2!$E$3:$E$7,Sheet2!$F$3:$F$7,,-1) -> 1.25 | D5: =_xlfn.XLOOKUP(insurance_policy_data!P317,Sheet2!$H$3:$H$5,Sheet2!$I$3:$I$5,,-1) -> 1 | E5: =_xlfn.XLOOKUP(insurance_policy_data!M317,Sheet2!$K$3:$K$7,Sheet2!$L$3:$L$7,,-1) -> 1.3 | F5: =_xlfn.XLOOKUP(insurance_policy_data!H317,Sheet2!$N$3:$N$9,Sheet2!$O$3:$O$9,,-1) -> 1.25 | G5: =_xlfn.XLOOKUP(insurance_policy_data!L317,Sheet2!$Q$3:$Q$4,Sheet2!$R$3:$R$4) -> 0.75 | H5: =_xlfn.XLOOKUP(insurance_policy_data!N317,Sheet2!$T$3:$T$5,Sheet2!$U$3:$U$5,,-1) -> 1 | I5: =(B5*C5*D5*E5*F5*G5*H5)*80 -> 147.46875
B6: =_xlfn.XLOOKUP(insurance_policy_data!B221,Sheet2!$B$3:$B$8,Sheet2!$C$3:$C$8,,-1) -> 1.21 | C6: =_xlfn.XLOOKUP(insurance_policy_data!I221,Sheet2!$E$3:$E$7,Sheet2!$F$3:$F$7,,-1) -> 1.25 | D6: =_xlfn.XLOOKUP(insurance_policy_data!P221,Sheet2!$H$3:$H$5,Sheet2!$I$3:$I$5,,-1) -> 1 | E6: =_xlfn.XLOOKUP(insurance_policy_data!M221,Sheet2!$K$3:$K$7,Sheet2!$L$3:$L$7,,-1) -> 1.39 | F6: =_xlfn.XLOOKUP(insurance_policy_data!H221,Sheet2!$N$3:$N$9,Sheet2!$O$3:$O$9,,-1) -> 1.2 | G6: =_xlfn.XLOOKUP(insurance_policy_data!L221,Sheet2!$Q$3:$Q$4,Sheet2!$R$3:$R$4) -> 0.75 | H6: =_xlfn.XLOOKUP(insurance_policy_data!N221,Sheet2!$T$3:$T$5,Sheet2!$U$3:$U$5,,-1) -> 1 | I6: =(B6*C6*D6*E6*F6*G6*H6)*80 -> 151.371
B7: =_xlfn.XLOOKUP(insurance_policy_data!B12,Sheet2!$B$3:$B$8,Sheet2!$C$3:$C$8,,-1) -> 1.21 | C7: =_xlfn.XLOOKUP(insurance_policy_data!I12,Sheet2!$E$3:$E$7,Sheet2!$F$3:$F$7,,-1) -> 1.25 | D7: =_xlfn.XLOOKUP(insurance_policy_data!P12,Sheet2!$H$3:$H$5,Sheet2!$I$3:$I$5,,-1) -> 1 | E7: =_xlfn.XLOOKUP(insurance_policy_data!M12,Sheet2!$K$3:$K$7,Sheet2!$L$3:$L$7,,-1) -> 1.26 | F7: =_xlfn.XLOOKUP(insurance_policy_data!H12,Sheet2!$N$3:$N$9,Sheet2!$O$3:$O$9,,-1) -> 1.33 | G7: =_xlfn.XLOOKUP(insurance_policy_data!L12,Sheet2!$Q$3:$Q$4,Sheet2!$R$3:$R$4) -> 0.75 | H7: =_xlfn.XLOOKUP(insurance_policy_data!N12,Sheet2!$T$3:$T$5,Sheet2!$U$3:$U$5,,-1) -> 1 | I7: =(B7*C7*D7*E7*F7*G7*H7)*80 -> 152.07885
B8: =_xlfn.XLOOKUP(insurance_policy_data!B154,Sheet2!$B$3:$B$8,Sheet2!$C$3:$C$8,,-1) -> 1.25 | C8: =_xlfn.XLOOKUP(insurance_policy_data!I154,Sheet2!$E$3:$E$7,Sheet2!$F$3:$F$7,,-1) -> 1.3 | D8: =_xlfn.XLOOKUP(insurance_policy_data!P154,Sheet2!$H$3:$H$5,Sheet2!$I$3:$I$5,,-1) -> 1 | E8: =_xlfn.XLOOKUP(insurance_policy_data!M154,Sheet2!$K$3:$K$7,Sheet2!$L$3:$L$7,,-1) -> 1.26 | F8: =_xlfn.XLOOKUP(insurance_policy_data!H154,Sheet2!$N$3:$N$9,Sheet2!$O$3:$O$9,,-1) -> 1.25 | G8: =_xlfn.XLOOKUP(insurance_policy_data!L154,Sheet2!$Q$3:$Q$4,Sheet2!$R$3:$R$4) -> 0.75 | H8: =_xlfn.XLOOKUP(insurance_policy_data!N154,Sheet2!$T$3:$T$5,Sheet2!$U$3:$U$5,,-1) -> 1 | I8: =(B8*C8*D8*E8*F8*G8*H8)*80 -> 153.5625
B9: =_xlfn.XLOOKUP(insurance_policy_data!B173,Sheet2!$B$3:$B$8,Sheet2!$C$3:$C$8,,-1) -> 1.21 | C9: =_xlfn.XLOOKUP(insurance_policy_data!I173,Sheet2!$E$3:$E$7,Sheet2!$F$3:$F$7,,-1) -> 1.25 | D9: =_xlfn.XLOOKUP(insurance_policy_data!P173,Sheet2!$H$3:$H$5,Sheet2!$I$3:$I$5,,-1) -> 1 | E9: =_xlfn.XLOOKUP(insurance_policy_data!M173,Sheet2!$K$3:$K$7,Sheet2!$L$3:$L$7,,-1) -> 1.3 | F9: =_xlfn.XLOOKUP(insurance_policy_data!H173,Sheet2!$N$3:$N$9,Sheet2!$O$3:$O$9,,-1) -> 1.2 | G9: =_xlfn.XLOOKUP(insurance_policy_data!L173,Sheet2!$Q$3:$Q$4,Sheet2!$R$3:$R$4) -> 0.75 | H9: =_xlfn.XLOOKUP(insurance_policy_data!N173,Sheet2!$T$3:$T$5,Sheet2!$U$3:$U$5,,-1) -> 1.1 | I9: =(B9*C9*D9*E9*F9*G9*H9)*80 -> 155.727
B10: =_xlfn.XLOOKUP(insurance_policy_data!B115,Sheet2!$B$3:$B$8,Sheet2!$C$3:$C$8,,-1) -> 1.21 | C10: =_xlfn.XLOOKUP(insurance_policy_data!I115,Sheet2!$E$3:$E$7,Sheet2!$F$3:$F$7,,-1) -> 1.25 | D10: =_xlfn.XLOOKUP(insurance_policy_data!P115,Sheet2!$H$3:$H$5,Sheet2!$I$3:$I$5,,-1) -> 1 | E10: =_xlfn.XLOOKUP(insurance_policy_data!M115,Sheet2!$K$3:$K$7,Sheet2!$L$3:$L$7,,-1) -> 1.26 | F10: =_xlfn.XLOOKUP(insurance_policy_data!H115,Sheet2!$N$3:$N$9,Sheet2!$O$3:$O$9,,-1) -> 1.25 | G10: =_xlfn.XLOOKUP(insurance_policy_data!L115,Sheet2!$Q$3:$Q$4,Sheet2!$R$3:$R$4) -> 0.75 | H10: =_xlfn.XLOOKUP(insurance_policy_data!N115,Sheet2!$T$3:$T$5,Sheet2!$U$3:$U$5,,-1) -> 1.1 | I10: =(B10*C10*D10*E10*F10*G10*H10)*80 -> 157.22438
B11: =_xlfn.XLOOKUP(insurance_policy_data!B198,Sheet2!$B$3:$B$8,Sheet2!$C$3:$C$8,,-1) -> 1.27 | C11: =_xlfn.XLOOKUP(insurance_policy_data!I198,Sheet2!$E$3:$E$7,Sheet2!$F$3:$F$7,,-1) -> 1.25 | D11: =_xlfn.XLOOKUP(insurance_policy_data!P198,Sheet2!$H$3:$H$5,Sheet2!$I$3:$I$5,,-1) -> 1 | E11: =_xlfn.XLOOKUP(insurance_policy_data!M198,Sheet2!$K$3:$K$7,Sheet2!$L$3:$L$7,,-1) -> 1.39 | F11: =_xlfn.XLOOKUP(insurance_policy_data!H198,Sheet2!$N$3:$N$9,Sheet2!$O$3:$O$9,,-1) -> 1.1 | G11: =_xlfn.XLOOKUP(insurance_policy_data!L198,Sheet2!$Q$3:$Q$4,Sheet2!$R$3:$R$4) -> 0.75 | H11: =_xlfn.XLOOKUP(insurance_policy_data!N198,Sheet2!$T$3:$T$5,Sheet2!$U$3:$U$5,,-1) -> 1.1 | I11: =(B11*C11*D11*E11*F11*G11*H11)*80 -> 160.20097
B12: =_xlfn.XLOOKUP(insurance_policy_data!B206,Sheet2!$B$3:$B$8,Sheet2!$C$3:$C$8,,-1) -> 1.21 | C12: =_xlfn.XLOOKUP(insurance_policy_data!I206,Sheet2!$E$3:$E$7,Sheet2!$F$3:$F$7,,-1) -> 1.25 | D12: =_xlfn.XLOOKUP(insurance_policy_data!P206,Sheet2!$H$3:$H$5,Sheet2!$I$3:$I$5,,-1) -> 1 | E12: =_xlfn.XLOOKUP(insurance_policy_data!M206,Sheet2!$K$3:$K$7,Sheet2!$L$3:$L$7,,-1) -> 1.39 | F12: =_xlfn.XLOOKUP(insurance_policy_data!H206,Sheet2!$N$3:$N$9,Sheet2!$O$3:$O$9,,-1) -> 1.29 | G12: =_xlfn.XLOOKUP(insurance_policy_data!L206,Sheet2!$Q$3:$Q$4,Sheet2!$R$3:$R$4) -> 0.75 | H12: =_xlfn.XLOOKUP(insurance_policy_data!N206,Sheet2!$T$3:$T$5,Sheet2!$U$3:$U$5,,-1) -> 1 | I12: =(B12*C12*D12*E12*F12*G12*H12)*80 -> 162.72382
B13: =_xlfn.XLOOKUP(insurance_policy_data!B292,Sheet2!$B$3:$B$8,Sheet2!$C$3:$C$8,,-1) -> 1.25 | C13: =_xlfn.XLOOKUP(insurance_policy_data!I292,Sheet2!$E$3:$E$7,Sheet2!$F$3:$F$7,,-1) -> 1.3 | D13: =_xlfn.XLOOKUP(insurance_policy_data!P292,Sheet2!$H$3:$H$5,Sheet2!$I$3:$I$5,,-1) -> 1 | E13: =_xlfn.XLOOKUP(insurance_policy_data!M292,Sheet2!$K$3:$K$7,Sheet2!$L$3:$L$7,,-1) -> 1.4 | F13: =_xlfn.XLOOKUP(insurance_policy_data!H292,Sheet2!$N$3:$N$9,Sheet2!$O$3:$O$9,,-1) -> 1.2 | G13: =_xlfn.XLOOKUP(insurance_policy_data!L292,Sheet2!$Q$3:$Q$4,Sheet2!$R$3:$R$4) -> 0.75 | H13: =_xlfn.XLOOKUP(insurance_policy_data!N292,Sheet2!$T$3:$T$5,Sheet2!$U$3:$U$5,,-1) -> 1 | I13: =(B13*C13*D13*E13*F13*G13*H13)*80 -> 163.8
B14: =_xlfn.XLOOKUP(insurance_policy_data!B39,Sheet2!$B$3:$B$8,Sheet2!$C$3:$C$8,,-1) -> 1.21 | C14: =_xlfn.XLOOKUP(insurance_policy_data!I39,Sheet2!$E$3:$E$7,Sheet2!$F$3:$F$7,,-1) -> 1.25 | D14: =_xlfn.XLOOKUP(insurance_policy_data!P39,Sheet2!$H$3:$H$5,Sheet2!$I$3:$I$5,,-1) -> 1 | E14: =_xlfn.XLOOKUP(insurance_policy_data!M39,Sheet2!$K$3:$K$7,Sheet2!$L$3:$L$7,,-1) -> 1.26 | F14: =_xlfn.XLOOKUP(insurance_policy_data!H39,Sheet2!$N$3:$N$9,Sheet2!$O$3:$O$9,,-1) -> 1.33 | G14: =_xlfn.XLOOKUP(insurance_policy_data!L39,Sheet2!$Q$3:$Q$4,Sheet2!$R$3:$R$4) -> 0.75 | H14: =_xlfn.XLOOKUP(insurance_policy_data!N39,Sheet2!$T$3:$T$5,Sheet2!$U$3:$U$5,,-1) -> 1.1 | I14: =(B14*C14*D14*E14*F14*G14*H14)*80 -> 167.28674
B15: =_xlfn.XLOOKUP(insurance_policy_data!B105,Sheet2!$B$3:$B$8,Sheet2!$C$3:$C$8,,-1) -> 1.21 | C15: =_xlfn.XLOOKUP(insurance_policy_data!I105,Sheet2!$E$3:$E$7,Sheet2!$F$3:$F$7,,-1) -> 1.25 | D15: =_xlfn.XLOOKUP(insurance_policy_data!P105,Sheet2!$H$3:$H$5,Sheet2!$I$3:$I$5,,-1) -> 1 | E15: =_xlfn.XLOOKUP(insurance_policy_data!M105,Sheet2!$K$3:$K$7,Sheet2!$L$3:$L$7,,-1) -> 1.4 | F15: =_xlfn.XLOOKUP(insurance_policy_data!H105,Sheet2!$N$3:$N$9,Sheet2!$O$3:$O$9,,-1) -> 1.2 | G15: =_xlfn.XLOOKUP(insurance_policy_data!L105,Sheet2!$Q$3:$Q$4,Sheet2!$R$3:$R$4) -> 0.75 | H15: =_xlfn.XLOOKUP(insurance_policy_data!N105,Sheet2!$T$3:$T$5,Sheet2!$U$3:$U$5,,-1) -> 1.1 | I15: =(B15*C15*D15*E15*F15*G15*H15)*80 -> 167.706
B16: =_xlfn.XLOOKUP(insurance_policy_data!B235,Sheet2!$B$3:$B$8,Sheet2!$C$3:$C$8,,-1) -> 1.21 | C16: =_xlfn.XLOOKUP(insurance_policy_data!I235,Sheet2!$E$3:$E$7,Sheet2!$F$3:$F$7,,-1) -> 1.25 | D16: =_xlfn.XLOOKUP(insurance_policy_data!P235,Sheet2!$H$3:$H$5,Sheet2!$I$3:$I$5,,-1) -> 1 | E16: =_xlfn.XLOOKUP(insurance_policy_data!M235,Sheet2!$K$3:$K$7,Sheet2!$L$3:$L$7,,-1) -> 1.4 | F16: =_xlfn.XLOOKUP(insurance_policy_data!H235,Sheet2!$N$3:$N$9,Sheet2!$O$3:$O$9,,-1) -> 1.1 | G16: =_xlfn.XLOOKUP(insurance_policy_data!L235,Sheet2!$Q$3:$Q$4,Sheet2!$R$3:$R$4) -> 0.75 | H16: =_xlfn.XLOOKUP(insurance_policy_data!N235,Sheet2!$T$3:$T$5,Sheet2!$U$3:$U$5,,-1) -> 1.2 | I16: =(B16*C16*D16*E16*F16*G16*H16)*80 -> 167.706
B17: =_xlfn.XLOOKUP(insurance_policy_data!B301,Sheet2!$B$3:$B$8,Sheet2!$C$3:$C$8,,-1) -> 1.21 | C17: =_xlfn.XLOOKUP(insurance_policy_data!I301,Sheet2!$E$3:$E$7,Sheet2!$F$3:$F$7,,-1) -> 1.25 | D17: =_xlfn.XLOOKUP(insurance_policy_data!P301,Sheet2!$H$3:$H$5,Sheet2!$I$3:$I$5,,-1) -> 1 | E17: =_xlfn.XLOOKUP(insurance_policy_data!M301,Sheet2!$K$3:$K$7,Sheet2!$L$3:$L$7,,-1) -> 1.3 | F17: =_xlfn.XLOOKUP(insurance_policy_data!H301,Sheet2!$N$3:$N$9,Sheet2!$O$3:$O$9,,-1) -> 1.2 | G17: =_xlfn.XLOOKUP(insurance_policy_data!L301,Sheet2!$Q$3:$Q$4,Sheet2!$R$3:$R$4) -> 0.75 | H17: =_xlfn.XLOOKUP(insurance_policy_data!N301,Sheet2!$T$3:$T$5,Sheet2!$U$3:$U$5,,-1) -> 1.2 | I17: =(B17*C17*D17*E17*F17*G17*H17)*80 -> 169.884
B18: =_xlfn.XLOOKUP(insurance_policy_data!B10,Sheet2!$B$3:$B$8,Sheet2!$C$3:$C$8,,-1) -> 1.21 | C18: =_xlfn.XLOOKUP(insurance_policy_data!I10,Sheet2!$E$3:$E$7,Sheet2!$F$3:$F$7,,-1) -> 1.25 | D18: =_xlfn.XLOOKUP(insurance_policy_data!P10,Sheet2!$H$3:$H$5,Sheet2!$I$3:$I$5,,-1) -> 1 | E18: =_xlfn.XLOOKUP(insurance_policy_data!M10,Sheet2!$K$3:$K$7,Sheet2!$L$3:$L$7,,-1) -> 1.4 | F18: =_xlfn.XLOOKUP(insurance_policy_data!H10,Sheet2!$N$3:$N$9,Sheet2!$O$3:$O$9,,-1) -> 1.36 | G18: =_xlfn.XLOOKUP(insurance_policy_data!L10,Sheet2!$Q$3:$Q$4,Sheet2!$R$3:$R$4) -> 0.75 | H18: =_xlfn.XLOOKUP(insurance_policy_data!N10,Sheet2!$T$3:$T$5,Sheet2!$U$3:$U$5,,-1) -> 1 | I18: =(B18*C18*D18*E18*F18*G18*H18)*80 -> 172.788
B19: =_xlfn.XLOOKUP(insurance_policy_data!B93,Sheet2!$B$3:$B$8,Sheet2!$C$3:$C$8,,-1) -> 1.21 | C19: =_xlfn.XLOOKUP(insurance_policy_data!I93,Sheet2!$E$3:$E$7,Sheet2!$F$3:$F$7,,-1) -> 1.25 | D19: =_xlfn.XLOOKUP(insurance_policy_data!P93,Sheet2!$H$3:$H$5,Sheet2!$I$3:$I$5,,-1) -> 1 | E19: =_xlfn.XLOOKUP(insurance_policy_data!M93,Sheet2!$K$3:$K$7,Sheet2!$L$3:$L$7,,-1) -> 1.39 | F19: =_xlfn.XLOOKUP(insurance_policy_data!H93,Sheet2!$N$3:$N$9,Sheet2!$O$3:$O$9,,-1) -> 1.25 | G19: =_xlfn.XLOOKUP(insurance_policy_data!L93,Sheet2!$Q$3:$Q$4,Sheet2!$R$3:$R$4) -> 0.75 | H19: =_xlfn.XLOOKUP(insurance_policy_data!N93,Sheet2!$T$3:$T$5,Sheet2!$U$3:$U$5,,-1) -> 1.1 | I19: =(B19*C19*D19*E19*F19*G19*H19)*80 -> 173.44594
B20: =_xlfn.XLOOKUP(insurance_policy_data!B81,Sheet2!$B$3:$B$8,Sheet2!$C$3:$C$8,,-1) -> 1.34 | C20: =_xlfn.XLOOKUP(insurance_policy_data!I81,Sheet2!$E$3:$E$7,Sheet2!$F$3:$F$7,,-1) -> 1.3 | D20: =_xlfn.XLOOKUP(insurance_policy_data!P81,Sheet2!$H$3:$H$5,Sheet2!$I$3:$I$5,,-1) -> 1 | E20: =_xlfn.XLOOKUP(insurance_policy_data!M81,Sheet2!$K$3:$K$7,Sheet2!$L$3:$L$7,,-1) -> 1.4 | F20: =_xlfn.XLOOKUP(insurance_policy_data!H81,Sheet2!$N$3:$N$9,Sheet2!$O$3:$O$9,,-1) -> 1.2 | G20: =_xlfn.XLOOKUP(insurance_policy_data!L81,Sheet2!$Q$3:$Q$4,Sheet2!$R$3:$R$4) -> 0.75 | H20: =_xlfn.XLOOKUP(insurance_policy_data!N81,Sheet2!$T$3:$T$5,Sheet2!$U$3:$U$5,,-1) -> 1 | I20: =(B20*C20*D20*E20*F20*G20*H20)*80 -> 175.5936
B21: =_xlfn.XLOOKUP(insurance_policy_data!B203,Sheet2!$B$3:$B$8,Sheet2!$C$3:$C$8,,-1) -> 1.34 | C21: =_xlfn.XLOOKUP(insurance_policy_data!I203,Sheet2!$E$3:$E$7,Sheet2!$F$3:$F$7,,-1) -> 1.3 | D21: =_xlfn.XLOOKUP(insurance_policy_data!P203,Sheet2!$H$3:$H$5,Sheet2!$I$3:$I$5,,-1) -> 1 | E21: =_xlfn.XLOOKUP(insurance_policy_data!M203,Sheet2!$K$3:$K$7,Sheet2!$L$3:$L$7,,-1) -> 1.4 | F21: =_xlfn.XLOOKUP(insurance_policy_data!H203,Sheet2!$N$3:$N$9,Sheet2!$O$3:$O$9,,-1) -> 1.2 | G21: =_xlfn.XLOOKUP(insurance_policy_data!L203,Sheet2!$Q$3:$Q$4,Sheet2!$R$3:$R$4) -> 0.75 | H21: =_xlfn.XLOOKUP(insurance_policy_data!N203,Sheet2!$T$3:$T$5,Sheet2!$U$3:$U$5,,-1) -> 1 | I21: =(B21*C21*D21*E21*F21*G21*H21)*80 -> 175.5936
B22: =_xlfn.XLOOKUP(insurance_policy_data!B204,Sheet2!$B$3:$B$8,Sheet2!$C$3:$C$8,,-1) -> 1.34 | C22: =_xlfn.XLOOKUP(insurance_policy_data!I204,Sheet2!$E$3:$E$7,Sheet2!$F$3:$F$7,,-1) -> 1.3 | D22: =_xlfn.XLOOKUP(insurance_policy_data!P204,Sheet2!$H$3:$H$5,Sheet2!$I$3:$I$5,,-1) -> 1 | E22: =_xlfn.XLOOKUP(insurance_policy_data!M204,Sheet2!$K$3:$K$7,Sheet2!$L$3:$L$7,,-1) -> 1.4 | F22: =_xlfn.XLOOKUP(insurance_policy_data!H204,Sheet2!$N$3:$N$9,Sheet2!$O$3:$O$9,,-1) -> 1.2 | G22: =_xlfn.XLOOKUP(insurance_policy_data!L204,Sheet2!$Q$3:$Q$4,Sheet2!$R$3:$R$4) -> 0.75 | H22: =_xlfn.XLOOKUP(insurance_policy_data!N204,Sheet2!$T$3:$T$5,Sheet2!$U$3:$U$5,,-1) -> 1 | I22: =(B22*C22*D22*E22*F22*G22*H22)*80 -> 175.5936
B23: =_xlfn.XLOOKUP(insurance_policy_data!B290,Sheet2!$B$3:$B$8,Sheet2!$C$3:$C$8,,-1) -> 1.27 | C23: =_xlfn.XLOOKUP(insurance_policy_data!I290,Sheet2!$E$3:$E$7,Sheet2!$F$3:$F$7,,-1) -> 1.25 | D23: =_xlfn.XLOOKUP(insurance_policy_data!P290,Sheet2!$H$3:$H$5,Sheet2!$I$3:$I$5,,-1) -> 1 | E23: =_xlfn.XLOOKUP(insurance_policy_data!M290,Sheet2!$K$3:$K$7,Sheet2!$L$3:$L$7,,-1) -> 1.3 | F23: =_xlfn.XLOOKUP(insurance_policy_data!H290,Sheet2!$N$3:$N$9,Sheet2!$O$3:$O$9,,-1) -> 1.29 | G23: =_xlfn.XLOOKUP(insurance_policy_data!L290,Sheet2!$Q$3:$Q$4,Sheet2!$R$3:$R$4) -> 0.75 | H23: =_xlfn.XLOOKUP(insurance_policy_data!N290,Sheet2!$T$3:$T$5,Sheet2!$U$3:$U$5,,-1) -> 1.1 | I23: =(B23*C23*D23*E23*F23*G23*H23)*80 -> 175.70767
B24: =_xlfn.XLOOKUP(insurance_policy_data!B26,Sheet2!$B$3:$B$8,Sheet2!$C$3:$C$8,,-1) -> 1.35 | C24: =_xlfn.XLOOKUP(insurance_policy_data!I26,Sheet2!$E$3:$E$7,Sheet2!$F$3:$F$7,,-1) -> 1.31 | D24: =_xlfn.XLOOKUP(insurance_policy_data!P26,Sheet2!$H$3:$H$5,Sheet2!$I$3:$I$5,,-1) -> 1 | E24: =_xlfn.XLOOKUP(insurance_policy_data!M26,Sheet2!$K$3:$K$7,Sheet2!$L$3:$L$7,,-1) -> 1.26 | F24: =_xlfn.XLOOKUP(insurance_policy_data!H26,Sheet2!$N$3:$N$9,Sheet2!$O$3:$O$9,,-1) -> 1.1 | G24: =_xlfn.XLOOKUP(insurance_policy_data!L26,Sheet2!$Q$3:$Q$4,Sheet2!$R$3:$R$4) -> 0.75 | H24: =_xlfn.XLOOKUP(insurance_policy_data!N26,Sheet2!$T$3:$T$5,Sheet2!$U$3:$U$5,,-1) -> 1.2 | I24: =(B24*C24*D24*E24*F24*G24*H24)*80 -> 176.48215
B25: =_xlfn.XLOOKUP(insurance_policy_data!B8,Sheet2!$B$3:$B$8,Sheet2!$C$3:$C$8,,-1) -> 1.25 | C25: =_xlfn.XLOOKUP(insurance_policy_data!I8,Sheet2!$E$3:$E$7,Sheet2!$F$3:$F$7,,-1) -> 1.3 | D25: =_xlfn.XLOOKUP(insurance_policy_data!P8,Sheet2!$H$3:$H$5,Sheet2!$I$3:$I$5,,-1) -> 1 | E25: =_xlfn.XLOOKUP(insurance_policy_data!M8,Sheet2!$K$3:$K$7,Sheet2!$L$3:$L$7,,-1) -> 1.26 | F25: =_xlfn.XLOOKUP(insurance_policy_data!H8,Sheet2!$N$3:$N$9,Sheet2!$O$3:$O$9,,-1) -> 1.2 | G25: =_xlfn.XLOOKUP(insurance_policy_data!L8,Sheet2!$Q$3:$Q$4,Sheet2!$R$3:$R$4) -> 0.75 | H25: =_xlfn.XLOOKUP(insurance_policy_data!N8,Sheet2!$T$3:$T$5,Sheet2!$U$3:$U$5,,-1) -> 1.2 | I25: =(B25*C25*D25*E25*F25*G25*H25)*80 -> 176.904
B26: =_xlfn.XLOOKUP(insurance_policy_data!B168,Sheet2!$B$3:$B$8,Sheet2!$C$3:$C$8,,-1) -> 1.21 | C26: =_xlfn.XLOOKUP(insurance_policy_data!I168,Sheet2!$E$3:$E$7,Sheet2!$F$3:$F$7,,-1) -> 1.25 | D26: =_xlfn.XLOOKUP(insurance_policy_data!P168,Sheet2!$H$3:$H$5,Sheet2!$I$3:$I$5,,-1) -> 1 | E26: =_xlfn.XLOOKUP(insurance_policy_data!M168,Sheet2!$K$3:$K$7,Sheet2!$L$3:$L$7,,-1) -> 1.39 | F26: =_xlfn.XLOOKUP(insurance_policy_data!H168,Sheet2!$N$3:$N$9,Sheet2!$O$3:$O$9,,-1) -> 1.29 | G26: =_xlfn.XLOOKUP(insurance_policy_data!L168,Sheet2!$Q$3:$Q$4,Sheet2!$R$3:$R$4) -> 0.75 | H26: =_xlfn.XLOOKUP(insurance_policy_data!N168,Sheet2!$T$3:$T$5,Sheet2!$U$3:$U$5,,-1) -> 1.1 | I26: =(B26*C26*D26*E26*F26*G26*H26)*80 -> 178.99621
B27: =_xlfn.XLOOKUP(insurance_policy_data!B169,Sheet2!$B$3:$B$8,Sheet2!$C$3:$C$8,,-1) -> 1.21 | C27: =_xlfn.XLOOKUP(insurance_policy_data!I169,Sheet2!$E$3:$E$7,Sheet2!$F$3:$F$7,,-1) -> 1.25 | D27: =_xlfn.XLOOKUP(insurance_policy_data!P169,Sheet2!$H$3:$H$5,Sheet2!$I$3:$I$5,,-1) -> 1 | E27: =_xlfn.XLOOKUP(insurance_policy_data!M169,Sheet2!$K$3:$K$7,Sheet2!$L$3:$L$7,,-1) -> 1.39 | F27: =_xlfn.XLOOKUP(insurance_policy_data!H169,Sheet2!$N$3:$N$9,Sheet2!$O$3:$O$9,,-1) -> 1.29 | G27: =_xlfn.XLOOKUP(insurance_policy_data!L169,Sheet2!$Q$3:$Q$4,Sheet2!$R$3:$R$4) -> 0.75 | H27: =_xlfn.XLOOKUP(insurance_policy_data!N169,Sheet2!$T$3:$T$5,Sheet2!$U$3:$U$5,,-1) -> 1.1 | I27: =(B27*C27*D27*E27*F27*G27*H27)*80 -> 178.99621
B28: =_xlfn.XLOOKUP(insurance_policy_data!B68,Sheet2!$B$3:$B$8,Sheet2!$C$3:$C$8,,-1) -> 1.21 | C28: =_xlfn.XLOOKUP(insurance_policy_data!I68,Sheet2!$E$3:$E$7,Sheet2!$F$3:$F$7,,-1) -> 1.25 | D28: =_xlfn.XLOOKUP(insurance_policy_data!P68,Sheet2!$H$3:$H$5,Sheet2!$I$3:$I$5,,-1) -> 1 | E28: =_xlfn.XLOOKUP(insurance_policy_data!M68,Sheet2!$K$3:$K$7,Sheet2!$L$3:$L$7,,-1) -> 1.4 | F28: =_xlfn.XLOOKUP(insurance_policy_data!H68,Sheet2!$N$3:$N$9,Sheet2!$O$3:$O$9,,-1) -> 1.29 | G28: =_xlfn.XLOOKUP(insurance_policy_data!L68,Sheet2!$Q$3:$Q$4,Sheet2!$R$3:$R$4) -> 0.75 | H28: =_xlfn.XLOOKUP(insurance_policy_data!N68,Sheet2!$T$3:$T$5,Sheet2!$U$3:$U$5,,-1) -> 1.1 | I28: =(B28*C28*D28*E28*F28*G28*H28)*80 -> 180.28395
B29: =_xlfn.XLOOKUP(insurance_policy_data!B194,Sheet2!$B$3:$B$8,Sheet2!$C$3:$C$8,,-1) -> 1.27 | C29: =_xlfn.XLOOKUP(insurance_policy_data!I194,Sheet2!$E$3:$E$7,Sheet2!$F$3:$F$7,,-1) -> 1.25 | D29: =_xlfn.XLOOKUP(insurance_policy_data!P194,Sheet2!$H$3:$H$5,Sheet2!$I$3:$I$5,,-1) -> 1 | E29: =_xlfn.XLOOKUP(insurance_policy_data!M194,Sheet2!$K$3:$K$7,Sheet2!$L$3:$L$7,,-1) -> 1.4 | F29: =_xlfn.XLOOKUP(insurance_policy_data!H194,Sheet2!$N$3:$N$9,Sheet2!$O$3:$O$9,,-1) -> 1.36 | G29: =_xlfn.XLOOKUP(insurance_policy_data!L194,Sheet2!$Q$3:$Q$4,Sheet2!$R$3:$R$4) -> 0.75 | H29: =_xlfn.XLOOKUP(insurance_policy_data!N194,Sheet2!$T$3:$T$5,Sheet2!$U$3:$U$5,,-1) -> 1 | I29: =(B29*C29*D29*E29*F29*G29*H29)*80 -> 181.356
B30: =_xlfn.XLOOKUP(insurance_policy_data!B18,Sheet2!$B$3:$B$8,Sheet2!$C$3:$C$8,,-1) -> 1.27 | C30: =_xlfn.XLOOKUP(insurance_policy_data!I18,Sheet2!$E$3:$E$7,Sheet2!$F$3:$F$7,,-1) -> 1.25 | D30: =_xlfn.XLOOKUP(insurance_policy_data!P18,Sheet2!$H$3:$H$5,Sheet2!$I$3:$I$5,,-1) -> 1 | E30: =_xlfn.XLOOKUP(insurance_policy_data!M18,Sheet2!$K$3:$K$7,Sheet2!$L$3:$L$7,,-1) -> 1.39 | F30: =_xlfn.XLOOKUP(insurance_policy_data!H18,Sheet2!$N$3:$N$9,Sheet2!$O$3:$O$9,,-1) -> 1.25 | G30: =_xlfn.XLOOKUP(insurance_policy_data!L18,Sheet2!$Q$3:$Q$4,Sheet2!$R$3:$R$4) -> 0.75 | H30: =_xlfn.XLOOKUP(insurance_policy_data!N18,Sheet2!$T$3:$T$5,Sheet2!$U$3:$U$5,,-1) -> 1.1 | I30: =(B30*C30*D30*E30*F30*G30*H30)*80 -> 182.04656
B31: =_xlfn.XLOOKUP(insurance_policy_data!B228,Sheet2!$B$3:$B$8,Sheet2!$C$3:$C$8,,-1) -> 1.34 | C31: =_xlfn.XLOOKUP(insurance_policy_data!I228,Sheet2!$E$3:$E$7,Sheet2!$F$3:$F$7,,-1) -> 1.31 | D31: =_xlfn.XLOOKUP(insurance_policy_data!P228,Sheet2!$H$3:$H$5,Sheet2!$I$3:$I$5,,-1) -> 1 | E31: =_xlfn.XLOOKUP(insurance_policy_data!M228,Sheet2!$K$3:$K$7,Sheet2!$L$3:$L$7,,-1) -> 1.3 | F31: =_xlfn.XLOOKUP(insurance_policy_data!H228,Sheet2!$N$3:$N$9,Sheet2!$O$3:$O$9,,-1) -> 1.33 | G31: =_xlfn.XLOOKUP(insurance_policy_data!L228,Sheet2!$Q$3:$Q$4,Sheet2!$R$3:$R$4) -> 0.75 | H31: =_xlfn.XLOOKUP(insurance_policy_data!N228,Sheet2!$T$3:$T$5,Sheet2!$U$3:$U$5,,-1) -> 1 | I31: =(B31*C31*D31*E31*F31*G31*H31)*80 -> 182.1052
B32: =_xlfn.XLOOKUP(insurance_policy_data!B50,Sheet2!$B$3:$B$8,Sheet2!$C$3:$C$8,,-1) -> 1.21 | C32: =_xlfn.XLOOKUP(insurance_policy_data!I50,Sheet2!$E$3:$E$7,Sheet2!$F$3:$F$7,,-1) -> 1.25 | D32: =_xlfn.XLOOKUP(insurance_policy_data!P50,Sheet2!$H$3:$H$5,Sheet2!$I$3:$I$5,,-1) -> 1 | E32: =_xlfn.XLOOKUP(insurance_policy_data!M50,Sheet2!$K$3:$K$7,Sheet2!$L$3:$L$7,,-1) -> 1.3 | F32: =_xlfn.XLOOKUP(insurance_policy_data!H50,Sheet2!$N$3:$N$9,Sheet2!$O$3:$O$9,,-1) -> 1.29 | G32: =_xlfn.XLOOKUP(insurance_policy_data!L50,Sheet2!$Q$3:$Q$4,Sheet2!$R$3:$R$4) -> 0.75 | H32: =_xlfn.XLOOKUP(insurance_policy_data!N50,Sheet2!$T$3:$T$5,Sheet2!$U$3:$U$5,,-1) -> 1.2 | I32: =(B32*C32*D32*E32*F32*G32*H32)*80 -> 182.6253
B33: =_xlfn.XLOOKUP(insurance_policy_data!B285,Sheet2!$B$3:$B$8,Sheet2!$C$3:$C$8,,-1) -> 1.34 | C33: =_xlfn.XLOOKUP(insurance_policy_data!I285,Sheet2!$E$3:$E$7,Sheet2!$F$3:$F$7,,-1) -> 1.31 | D33: =_xlfn.XLOOKUP(insurance_policy_data!P285,Sheet2!$H$3:$H$5,Sheet2!$I$3:$I$5,,-1) -> 1 | E33: =_xlfn.XLOOKUP(insurance_policy_data!M285,Sheet2!$K$3:$K$7,Sheet2!$L$3:$L$7,,-1) -> 1.3 | F33: =_xlfn.XLOOKUP(insurance_policy_data!H285,Sheet2!$N$3:$N$9,Sheet2!$O$3:$O$9,,-1) -> 1.25 | G33: =_xlfn.XLOOKUP(insurance_policy_data!L285,Sheet2!$Q$3:$Q$4,Sheet2!$R$3:$R$4) -> 0.75 | H33: =_xlfn.XLOOKUP(insurance_policy_data!N285,Sheet2!$T$3:$T$5,Sheet2!$U$3:$U$5,,-1) -> 1.1 | I33: =(B33*C33*D33*E33*F33*G33*H33)*80 -> 188.26665
B34: =_xlfn.XLOOKUP(insurance_policy_data!B30,Sheet2!$B$3:$B$8,Sheet2!$C$3:$C$8,,-1) -> 1.35 | C34: =_xlfn.XLOOKUP(insurance_policy_data!I30,Sheet2!$E$3:$E$7,Sheet2!$F$3:$F$7,,-1) -> 1.31 | D34: =_xlfn.XLOOKUP(insurance_policy_data!P30,Sheet2!$H$3:$H$5,Sheet2!$I$3:$I$5,,-1) -> 1 | E34: =_xlfn.XLOOKUP(insurance_policy_data!M30,Sheet2!$K$3:$K$7,Sheet2!$L$3:$L$7,,-1) -> 1.26 | F34: =_xlfn.XLOOKUP(insurance_policy_data!H30,Sheet2!$N$3:$N$9,Sheet2!$O$3:$O$9,,-1) -> 1.29 | G34: =_xlfn.XLOOKUP(insurance_policy_data!L30,Sheet2!$Q$3:$Q$4,Sheet2!$R$3:$R$4) -> 0.75 | H34: =_xlfn.XLOOKUP(insurance_policy_data!N30,Sheet2!$T$3:$T$5,Sheet2!$U$3:$U$5,,-1) -> 1.1 | I34: =(B34*C34*D34*E34*F34*G34*H34)*80 -> 189.71831
B35: =_xlfn.XLOOKUP(insurance_policy_data!B83,Sheet2!$B$3:$B$8,Sheet2!$C$3:$C$8,,-1) -> 1.35 | C35: =_xlfn.XLOOKUP(insurance_policy_data!I83,Sheet2!$E$3:$E$7,Sheet2!$F$3:$F$7,,-1) -> 1.31 | D35: =_xlfn.XLOOKUP(insurance_policy_data!P83,Sheet2!$H$3:$H$5,Sheet2!$I$3:$I$5,,-1) -> 1 | E35: =_xlfn.XLOOKUP(insurance_policy_data!M83,Sheet2!$K$3:$K$7,Sheet2!$L$3:$L$7,,-1) -> 1.39 | F35: =_xlfn.XLOOKUP(insurance_policy_data!H83,Sheet2!$N$3:$N$9,Sheet2!$O$3:$O$9,,-1) -> 1.29 | G35: =_xlfn.XLOOKUP(insurance_policy_data!L83,Sheet2!$Q$3:$Q$4,Sheet2!$R$3:$R$4) -> 0.75 | H35: =_xlfn.XLOOKUP(insurance_policy_data!N83,Sheet2!$T$3:$T$5,Sheet2!$U$3:$U$5,,-1) -> 1 | I35: =(B35*C35*D35*E35*F35*G35*H35)*80 -> 190.26584
B36: =_xlfn.XLOOKUP(insurance_policy_data!B272,Sheet2!$B$3:$B$8,Sheet2!$C$3:$C$8,,-1) -> 1.35 | C36: =_xlfn.XLOOKUP(insurance_policy_data!I272,Sheet2!$E$3:$E$7,Sheet2!$F$3:$F$7,,-1) -> 1.31 | D36: =_xlfn.XLOOKUP(insurance_policy_data!P272,Sheet2!$H$3:$H$5,Sheet2!$I$3:$I$5,,-1) -> 1 | E36: =_xlfn.XLOOKUP(insurance_policy_data!M272,Sheet2!$K$3:$K$7,Sheet2!$L$3:$L$7,,-1) -> 1.26 | F36: =_xlfn.XLOOKUP(insurance_policy_data!H272,Sheet2!$N$3:$N$9,Sheet2!$O$3:$O$9,,-1) -> 1.2 | G36: =_xlfn.XLOOKUP(insurance_policy_data!L272,Sheet2!$Q$3:$Q$4,Sheet2!$R$3:$R$4) -> 0.75 | H36: =_xlfn.XLOOKUP(insurance_policy_data!N272,Sheet2!$T$3:$T$5,Sheet2!$U$3:$U$5,,-1) -> 1.2 | I36: =(B36*C36*D36*E36*F36*G36*H36)*80 -> 192.52598
B37: =_xlfn.XLOOKUP(insurance_policy_data!B47,Sheet2!$B$3:$B$8,Sheet2!$C$3:$C$8,,-1) -> 1.34 | C37: =_xlfn.XLOOKUP(insurance_policy_data!I47,Sheet2!$E$3:$E$7,Sheet2!$F$3:$F$7,,-1) -> 1.31 | D37: =_xlfn.XLOOKUP(insurance_policy_data!P47,Sheet2!$H$3:$H$5,Sheet2!$I$3:$I$5,,-1) -> 1 | E37: =_xlfn.XLOOKUP(insurance_policy_data!M47,Sheet2!$K$3:$K$7,Sheet2!$L$3:$L$7,,-1) -> 1.26 | F37: =_xlfn.XLOOKUP(insurance_policy_data!H47,Sheet2!$N$3:$N$9,Sheet2!$O$3:$O$9,,-1) -> 1.33 | G37: =_xlfn.XLOOKUP(insurance_policy_data!L47,Sheet2!$Q$3:$Q$4,Sheet2!$R$3:$R$4) -> 0.75 | H37: =_xlfn.XLOOKUP(insurance_policy_data!N47,Sheet2!$T$3:$T$5,Sheet2!$U$3:$U$5,,-1) -> 1.1 | I37: =(B37*C37*D37*E37*F37*G37*H37)*80 -> 194.15216
B38: =_xlfn.XLOOKUP(insurance_policy_data!B248,Sheet2!$B$3:$B$8,Sheet2!$C$3:$C$8,,-1) -> 1.34 | C38: =_xlfn.XLOOKUP(insurance_policy_data!I248,Sheet2!$E$3:$E$7,Sheet2!$F$3:$F$7,,-1) -> 1.3 | D38: =_xlfn.XLOOKUP(insurance_policy_data!P248,Sheet2!$H$3:$H$5,Sheet2!$I$3:$I$5,,-1) -> 1 | E38: =_xlfn.XLOOKUP(insurance_policy_data!M248,Sheet2!$K$3:$K$7,Sheet2!$L$3:$L$7,,-1) -> 1.4 | F38: =_xlfn.XLOOKUP(insurance_policy_data!H248,Sheet2!$N$3:$N$9,Sheet2!$O$3:$O$9,,-1) -> 1.33 | G38: =_xlfn.XLOOKUP(insurance_policy_data!L248,Sheet2!$Q$3:$Q$4,Sheet2!$R$3:$R$4) -> 0.75 | H38: =_xlfn.XLOOKUP(insurance_policy_data!N248,Sheet2!$T$3:$T$5,Sheet2!$U$3:$U$5,,-1) -> 1 | I38: =(B38*C38*D38*E38*F38*G38*H38)*80 -> 194.61624
B39: =_xlfn.XLOOKUP(insurance_policy_data!B223,Sheet2!$B$3:$B$8,Sheet2!$C$3:$C$8,,-1) -> 1.35 | C39: =_xlfn.XLOOKUP(insurance_policy_data!I223,Sheet2!$E$3:$E$7,Sheet2!$F$3:$F$7,,-1) -> 1.31 | D39: =_xlfn.XLOOKUP(insurance_policy_data!P223,Sheet2!$H$3:$H$5,Sheet2!$I$3:$I$5,,-1) -> 1 | E39: =_xlfn.XLOOKUP(insurance_policy_data!M223,Sheet2!$K$3:$K$7,Sheet2!$L$3:$L$7,,-1) -> 1.39 | F39: =_xlfn.XLOOKUP(insurance_policy_data!H223,Sheet2!$N$3:$N$9,Sheet2!$O$3:$O$9,,-1) -> 1.1 | G39: =_xlfn.XLOOKUP(insurance_policy_data!L223,Sheet2!$Q$3:$Q$4,Sheet2!$R$3:$R$4) -> 0.75 | H39: =_xlfn.XLOOKUP(insurance_policy_data!N223,Sheet2!$T$3:$T$5,Sheet2!$U$3:$U$5,,-1) -> 1.2 | I39: =(B39*C39*D39*E39*F39*G39*H39)*80 -> 194.69063
B40: =_xlfn.XLOOKUP(insurance_policy_data!B230,Sheet2!$B$3:$B$8,Sheet2!$C$3:$C$8,,-1) -> 1.21 | C40: =_xlfn.XLOOKUP(insurance_policy_data!I230,Sheet2!$E$3:$E$7,Sheet2!$F$3:$F$7,,-1) -> 1.25 | D40: =_xlfn.XLOOKUP(insurance_policy_data!P230,Sheet2!$H$3:$H$5,Sheet2!$I$3:$I$5,,-1) -> 1 | E40: =_xlfn.XLOOKUP(insurance_policy_data!M230,Sheet2!$K$3:$K$7,Sheet2!$L$3:$L$7,,-1) -> 1.39 | F40: =_xlfn.XLOOKUP(insurance_policy_data!H230,Sheet2!$N$3:$N$9,Sheet2!$O$3:$O$9,,-1) -> 1.29 | G40: =_xlfn.XLOOKUP(insurance_policy_data!L230,Sheet2!$Q$3:$Q$4,Sheet2!$R$3:$R$4) -> 0.75 | H40: =_xlfn.XLOOKUP(insurance_policy_data!N230,Sheet2!$T$3:$T$5,Sheet2!$U$3:$U$5,,-1) -> 1.2 | I40: =(B40*C40*D40*E40*F40*G40*H40)*80 -> 195.26859
B41: =_xlfn.XLOOKUP(insurance_policy_data!B42,Sheet2!$B$3:$B$8,Sheet2!$C$3:$C$8,,-1) -> 1.35 | C41: =_xlfn.XLOOKUP(insurance_policy_data!I42,Sheet2!$E$3:$E$7,Sheet2!$F$3:$F$7,,-1) -> 1.31 | D41: =_xlfn.XLOOKUP(insurance_policy_data!P42,Sheet2!$H$3:$H$5,Sheet2!$I$3:$I$5,,-1) -> 1 | E41: =_xlfn.XLOOKUP(insurance_policy_data!M42,Sheet2!$K$3:$K$7,Sheet2!$L$3:$L$7,,-1) -> 1.26 | F41: =_xlfn.XLOOKUP(insurance_policy_data!H42,Sheet2!$N$3:$N$9,Sheet2!$O$3:$O$9,,-1) -> 1.33 | G41: =_xlfn.XLOOKUP(insurance_policy_data!L42,Sheet2!$Q$3:$Q$4,Sheet2!$R$3:$R$4) -> 0.75 | H41: =_xlfn.XLOOKUP(insurance_policy_data!N42,Sheet2!$T$3:$T$5,Sheet2!$U$3:$U$5,,-1) -> 1.1 | I41: =(B41*C41*D41*E41*F41*G41*H41)*80 -> 195.60105
...

Sheet Sheet2
B2: Age | C2: Age Multiplier | E2: Experience | F2: exp multiplier | H2: at fault | I2: multiplier | K2: fico | L2: multiplier | N2: mileage | O2: mult | Q2: DUI | R2: mult | T2: coverage | U2: mult
B3: 18 | C3: 1.35 | E3: 0 | F3: 1.31 | H3: 0 | I3: 1 | K3: 300 | L3: 1.4 | N3: 3000 | O3: 1.1 | Q3: Y | R3: 1.5 | T3: LIAB | U3: 1.2
B4: 30 | C4: 1.34 | E4: 15 | F4: 1.3 | H4: 1 | I4: 1.3 | K4: 450 | L4: 1.39 | N4: 8000 | O4: 1.2 | Q4: N | R4: 0.75 | T4: COLL | U4: 1.1
B5: 40 | C5: 1.25 | E5: 30 | F5: 1.25 | H5: 2 | I5: 1.45 | K5: 600 | L5: 1.3 | N5: 11000 | O5: 1.25 | T5: COMP | U5: 1
B6: 50 | C6: 1.27 | E6: 45 | F6: 1.25 | K6: 700 | L6: 1.26 | N6: 15000 | O6: 1.29
B7: 60 | C7: 1.21 | E7: 59 | F7: 1.32 | K7: 850 | L7: 1.22 | N7: 19000 | O7: 1.33
B8: 75 | C8: 1.28 | N8: 23000 | O8: 1.36
N9: 28000 | O9: 1.4

Sheet Risk

Sheet Vehicle Info

Sheet Applicant Demographic
A1: Demographic
P5: Age
P6: Column1 | Q6: Column2
P7: Average: | Q7: =AVERAGE(Table4[Applicant_Age]) -> 47.660377
P8: Median: | Q8: =MEDIAN(Table4[Applicant_Age]) -> 49
P9: STDDEV: | Q9: =STDEV(Table4[Applicant_Age]) -> 17.224746
P11: FICO
P12: Average | Q12: =AVERAGE(insurance_policy_data!M:M) -> 562.27044
P13: Median | Q13: =MEDIAN(Table4[Credit_Score]) -> 563.5
P14: STDDEV: | Q14: =STDEV(Table4[Credit_Score]) -> 149.99711
